<?xml version="1.0" ?>
<robot name="Assembly_in_same_file" xmlns:xacro="http://www.ros.org/wiki/xacro">

<xacro:include filename="$(find Assembly_in_same_file_description)/urdf/materials.xacro" />
<xacro:include filename="$(find Assembly_in_same_file_description)/urdf/Assembly_in_same_file.trans" />
<xacro:include filename="$(find Assembly_in_same_file_description)/urdf/Assembly_in_same_file.gazebo" />
<link name="base_link">
  <inertial>
    <origin rpy="0 0 0" xyz="0.12500000000000003 0.02499999999999856 0.024912666207651243"/>
    <mass value="8.85385637713646"/>
    <inertia ixx="0.018426" ixy="0.0" ixz="0.0" iyy="0.018507" iyz="-0.0" izz="0.033199"/>
  </inertial>
  <visual>
    <origin rpy="0 0 0" xyz="0 0 0"/>
    <geometry>
      <mesh filename="package://Assembly_in_same_file_description/meshes/base_link.stl" scale="0.001 0.001 0.001"/>
    </geometry>
    <material name="silver"/>
  </visual>
  <collision>
    <origin rpy="0 0 0" xyz="0 0 0"/>
    <geometry>
      <mesh filename="package://Assembly_in_same_file_description/meshes/base_link.stl" scale="0.001 0.001 0.001"/>
    </geometry>
  </collision>
</link>

<link name="right_wheel_1">
  <inertial>
    <origin rpy="0 0 0" xyz="5.551115123125783e-17 -0.009999999999999988 2.42861286636753e-17"/>
    <mass value="1.2330751165339935"/>
    <inertia ixx="0.000812" ixy="-0.0" ixz="0.0" iyy="0.001541" iyz="0.0" izz="0.000812"/>
  </inertial>
  <visual>
    <origin rpy="0 0 0" xyz="-0.125 0.05 -0.025"/>
    <geometry>
      <mesh filename="package://Assembly_in_same_file_description/meshes/right_wheel_1.stl" scale="0.001 0.001 0.001"/>
    </geometry>
    <material name="silver"/>
  </visual>
  <collision>
    <origin rpy="0 0 0" xyz="-0.125 0.05 -0.025"/>
    <geometry>
      <mesh filename="package://Assembly_in_same_file_description/meshes/right_wheel_1.stl" scale="0.001 0.001 0.001"/>
    </geometry>
  </collision>
</link>

<link name="left_wheel_1">
  <inertial>
    <origin rpy="0 0 0" xyz="8.326672684688674e-17 0.009999999999999995 3.469446951953614e-17"/>
    <mass value="1.2330751165339937"/>
    <inertia ixx="0.000812" ixy="-0.0" ixz="0.0" iyy="0.001541" iyz="0.0" izz="0.000812"/>
  </inertial>
  <visual>
    <origin rpy="0 0 0" xyz="-0.125 -0.1 -0.025"/>
    <geometry>
      <mesh filename="package://Assembly_in_same_file_description/meshes/left_wheel_1.stl" scale="0.001 0.001 0.001"/>
    </geometry>
    <material name="silver"/>
  </visual>
  <collision>
    <origin rpy="0 0 0" xyz="-0.125 -0.1 -0.025"/>
    <geometry>
      <mesh filename="package://Assembly_in_same_file_description/meshes/left_wheel_1.stl" scale="0.001 0.001 0.001"/>
    </geometry>
  </collision>
</link>

<link name="lidar_1">
  <inertial>
    <origin rpy="0 0 0" xyz="5.551115123125783e-17 1.0408340855860843e-17 0.013489010989011008"/>
    <mass value="0.35065573626435437"/>
    <inertia ixx="6.8e-05" ixy="0.0" ixz="0.0" iyy="6.8e-05" iyz="-0.0" izz="9.1e-05"/>
  </inertial>
  <visual>
    <origin rpy="0 0 0" xyz="-0.125 -0.025 -0.05"/>
    <geometry>
      <mesh filename="package://Assembly_in_same_file_description/meshes/lidar_1.stl" scale="0.001 0.001 0.001"/>
    </geometry>
    <material name="silver"/>
  </visual>
  <collision>
    <origin rpy="0 0 0" xyz="-0.125 -0.025 -0.05"/>
    <geometry>
      <mesh filename="package://Assembly_in_same_file_description/meshes/lidar_1.stl" scale="0.001 0.001 0.001"/>
    </geometry>
  </collision>
</link>

<joint name="right_wheel" type="continuous">
  <origin rpy="0 0 0" xyz="0.125 -0.05 0.025"/>
  <parent link="base_link"/>
  <child link="right_wheel_1"/>
  <axis xyz="-0.0 -1.0 0.0"/>
</joint>

<joint name="left_wheel" type="continuous">
  <origin rpy="0 0 0" xyz="0.125 0.1 0.025"/>
  <parent link="base_link"/>
  <child link="left_wheel_1"/>
  <axis xyz="0.0 1.0 0.0"/>
</joint>

<joint name="lidar" type="fixed">
  <origin rpy="0 0 0" xyz="0.125 0.025 0.05"/>
  <parent link="base_link"/>
  <child link="lidar_1"/>
</joint>

</robot>
