<?xml version="1.0" ?>
<robot name="sample" xmlns:xacro="http://www.ros.org/wiki/xacro">

<xacro:include filename="$(find sample_description)/urdf/materials.xacro" />
<xacro:include filename="$(find sample_description)/urdf/sample.trans" />
<xacro:include filename="$(find sample_description)/urdf/sample.gazebo" />
<link name="base_link">
  <inertial>
    <origin rpy="0 0 0" xyz="0.03340161632196768 0.040717102989105886 -0.04911871931107357"/>
    <mass value="0.48066367599923826"/>
    <inertia ixx="0.000776" ixy="-0.0" ixz="0.0" iyy="0.000776" iyz="-0.0" izz="0.001352"/>
  </inertial>
  <visual>
    <origin rpy="0 0 0" xyz="0 0 0"/>
    <geometry>
      <mesh filename="package://sample_description/meshes/base_link.stl" scale="0.001 0.001 0.001"/>
    </geometry>
    <material name="silver"/>
  </visual>
  <collision>
    <origin rpy="0 0 0" xyz="0 0 0"/>
    <geometry>
      <mesh filename="package://sample_description/meshes/base_link.stl" scale="0.001 0.001 0.001"/>
    </geometry>
  </collision>
</link>

<link name="shoulder_link_1">
  <inertial>
    <origin rpy="0 0 0" xyz="-3.836780323313027e-07 0.031200999809898405 0.04040414596319557"/>
    <mass value="0.6897828784531455"/>
    <inertia ixx="0.000895" ixy="0.0" ixz="-0.0" iyy="0.000766" iyz="-0.000142" izz="0.000797"/>
  </inertial>
  <visual>
    <origin rpy="0 0 0" xyz="-0.033402 -0.040717 0.024119"/>
    <geometry>
      <mesh filename="package://sample_description/meshes/shoulder_link_1.stl" scale="0.001 0.001 0.001"/>
    </geometry>
    <material name="silver"/>
  </visual>
  <collision>
    <origin rpy="0 0 0" xyz="-0.033402 -0.040717 0.024119"/>
    <geometry>
      <mesh filename="package://sample_description/meshes/shoulder_link_1.stl" scale="0.001 0.001 0.001"/>
    </geometry>
  </collision>
</link>

<link name="arm_link_1">
  <inertial>
    <origin rpy="0 0 0" xyz="-0.025407176858154752 -0.005771114300507071 0.117259293678515"/>
    <mass value="0.9418000765257055"/>
    <inertia ixx="0.006505" ixy="3.9e-05" ixz="0.000371" iyy="0.00673" iyz="-0.000573" izz="0.000766"/>
  </inertial>
  <visual>
    <origin rpy="0 0 0" xyz="-0.033402 -0.040717 -0.023381"/>
    <geometry>
      <mesh filename="package://sample_description/meshes/arm_link_1.stl" scale="0.001 0.001 0.001"/>
    </geometry>
    <material name="silver"/>
  </visual>
  <collision>
    <origin rpy="0 0 0" xyz="-0.033402 -0.040717 -0.023381"/>
    <geometry>
      <mesh filename="package://sample_description/meshes/arm_link_1.stl" scale="0.001 0.001 0.001"/>
    </geometry>
  </collision>
</link>

<link name="elbow_link_1">
  <inertial>
    <origin rpy="0 0 0" xyz="0.11911226792368751 0.012468729906830747 0.02100293778053644"/>
    <mass value="0.2638036919050309"/>
    <inertia ixx="8.6e-05" ixy="-1e-06" ixz="-0.000308" iyy="0.001837" iyz="-0.0" izz="0.001781"/>
  </inertial>
  <visual>
    <origin rpy="0 0 0" xyz="-0.00186 -0.090717 -0.231059"/>
    <geometry>
      <mesh filename="package://sample_description/meshes/elbow_link_1.stl" scale="0.001 0.001 0.001"/>
    </geometry>
    <material name="silver"/>
  </visual>
  <collision>
    <origin rpy="0 0 0" xyz="-0.00186 -0.090717 -0.231059"/>
    <geometry>
      <mesh filename="package://sample_description/meshes/elbow_link_1.stl" scale="0.001 0.001 0.001"/>
    </geometry>
  </collision>
</link>

<link name="eef_1">
  <inertial>
    <origin rpy="0 0 0" xyz="0.012310572942673653 1.0298910638195657e-07 0.002170796347392867"/>
    <mass value="0.20699557428756424"/>
    <inertia ixx="0.000283" ixy="-0.0" ixz="5e-06" iyy="5.3e-05" iyz="0.0" izz="0.000254"/>
  </inertial>
  <visual>
    <origin rpy="0 0 0" xyz="-0.248061 -0.103217 -0.274471"/>
    <geometry>
      <mesh filename="package://sample_description/meshes/eef_1.stl" scale="0.001 0.001 0.001"/>
    </geometry>
    <material name="silver"/>
  </visual>
  <collision>
    <origin rpy="0 0 0" xyz="-0.248061 -0.103217 -0.274471"/>
    <geometry>
      <mesh filename="package://sample_description/meshes/eef_1.stl" scale="0.001 0.001 0.001"/>
    </geometry>
  </collision>
</link>

<link name="left_claw_1">
  <inertial>
    <origin rpy="0 0 0" xyz="0.022157844298101026 0.00750010298910668 0.003907482565735643"/>
    <mass value="0.0188325"/>
    <inertia ixx="2e-06" ixy="-0.0" ixz="-0.0" iyy="5e-06" iyz="0.0" izz="3e-06"/>
  </inertial>
  <visual>
    <origin rpy="0 0 0" xyz="-0.272682 -0.043217 -0.278812"/>
    <geometry>
      <mesh filename="package://sample_description/meshes/left_claw_1.stl" scale="0.001 0.001 0.001"/>
    </geometry>
    <material name="silver"/>
  </visual>
  <collision>
    <origin rpy="0 0 0" xyz="-0.272682 -0.043217 -0.278812"/>
    <geometry>
      <mesh filename="package://sample_description/meshes/left_claw_1.stl" scale="0.001 0.001 0.001"/>
    </geometry>
  </collision>
</link>

<link name="right_claw_1">
  <inertial>
    <origin rpy="0 0 0" xyz="0.022157844298100693 -0.00749989701089343 0.00390748256573531"/>
    <mass value="0.0188325"/>
    <inertia ixx="2e-06" ixy="-0.0" ixz="-0.0" iyy="5e-06" iyz="0.0" izz="3e-06"/>
  </inertial>
  <visual>
    <origin rpy="0 0 0" xyz="-0.272682 -0.163217 -0.278812"/>
    <geometry>
      <mesh filename="package://sample_description/meshes/right_claw_1.stl" scale="0.001 0.001 0.001"/>
    </geometry>
    <material name="silver"/>
  </visual>
  <collision>
    <origin rpy="0 0 0" xyz="-0.272682 -0.163217 -0.278812"/>
    <geometry>
      <mesh filename="package://sample_description/meshes/right_claw_1.stl" scale="0.001 0.001 0.001"/>
    </geometry>
  </collision>
</link>

<joint name="base_twist" type="continuous">
  <origin rpy="0 0 0" xyz="0.033402 0.040717 -0.024119"/>
  <parent link="base_link"/>
  <child link="shoulder_link_1"/>
  <axis xyz="0.0 0.0 1.0"/>
</joint>

<joint name="arm_rev" type="revolute">
  <origin rpy="0 0 0" xyz="0.0 0.0 0.0475"/>
  <parent link="shoulder_link_1"/>
  <child link="arm_link_1"/>
  <axis xyz="-0.0 -1.0 0.0"/>
  <limit effort="100" lower="-0.174533" upper="1.570796" velocity="100"/>
</joint>

<joint name="elbow_rev" type="revolute">
  <origin rpy="0 0 0" xyz="-0.031542 0.05 0.207678"/>
  <parent link="arm_link_1"/>
  <child link="elbow_link_1"/>
  <axis xyz="0.0 1.0 -0.0"/>
  <limit effort="100" lower="-2.792527" upper="2.792527" velocity="100"/>
</joint>

<joint name="wrist_twist" type="continuous">
  <origin rpy="0 0 0" xyz="0.246201 0.0125 0.043412"/>
  <parent link="elbow_link_1"/>
  <child link="eef_1"/>
  <axis xyz="0.984808 0.0 0.173648"/>
</joint>

<joint name="left_claw_sliding" type="prismatic">
  <origin rpy="0 0 0" xyz="0.024621 -0.06 0.004341"/>
  <parent link="eef_1"/>
  <child link="left_claw_1"/>
  <axis xyz="-0.0 1.0 -0.0"/>
  <limit effort="100" lower="0.0" upper="0.05" velocity="100"/>
</joint>

<joint name="right_claw_sliding" type="prismatic">
  <origin rpy="0 0 0" xyz="0.024621 0.06 0.004341"/>
  <parent link="eef_1"/>
  <child link="right_claw_1"/>
  <axis xyz="0.0 -1.0 0.0"/>
  <limit effort="100" lower="0.0" upper="0.05" velocity="100"/>
</joint>

</robot>
