<?xml version="1.0" ?>
<robot name="sample" xmlns:xacro="http://www.ros.org/wiki/xacro">

<xacro:include filename="$(find sample_description)/urdf/materials.xacro" />
<xacro:include filename="$(find sample_description)/urdf/sample.trans" />
<xacro:include filename="$(find sample_description)/urdf/sample.gazebo" />
<link name="base_link">
  <inertial>
    <origin rpy="0 0 0" xyz="0.033401616321967684 0.04071710298910584 0.025881280688926388"/>
    <mass value="0.48066367599923826"/>
    <inertia ixx="0.000776" ixy="-0.0" ixz="0.0" iyy="0.000776" iyz="-0.0" izz="0.001352"/>
  </inertial>
  <visual>
    <origin rpy="0 0 0" xyz="0 0 0"/>
    <geometry>
      <mesh filename="package://sample_description/meshes/base_link.stl" scale="0.001 0.001 0.001"/>
    </geometry>
    <material name="silver"/>
  </visual>
  <collision>
    <origin rpy="0 0 0" xyz="0 0 0"/>
    <geometry>
      <mesh filename="package://sample_description/meshes/base_link.stl" scale="0.001 0.001 0.001"/>
    </geometry>
  </collision>
</link>

<link name="shoulder_link_1">
  <inertial>
    <origin rpy="0 0 0" xyz="-8.137465708014935e-05 0.031200894691930603 0.04040414596319556"/>
    <mass value="0.6897828784531455"/>
    <inertia ixx="0.000895" ixy="0.0" ixz="0.0" iyy="0.000766" iyz="-0.000142" izz="0.000797"/>
  </inertial>
  <visual>
    <origin rpy="0 0 0" xyz="-0.033402 -0.040717 -0.050881"/>
    <geometry>
      <mesh filename="package://sample_description/meshes/shoulder_link_1.stl" scale="0.001 0.001 0.001"/>
    </geometry>
    <material name="silver"/>
  </visual>
  <collision>
    <origin rpy="0 0 0" xyz="-0.033402 -0.040717 -0.050881"/>
    <geometry>
      <mesh filename="package://sample_description/meshes/shoulder_link_1.stl" scale="0.001 0.001 0.001"/>
    </geometry>
  </collision>
</link>

<link name="arm_link_1">
  <inertial>
    <origin rpy="0 0 0" xyz="-0.025371561839561983 -0.005836992219154562 0.117263744113045"/>
    <mass value="0.9418000765257055"/>
    <inertia ixx="0.006505" ixy="3.8e-05" ixz="0.000371" iyy="0.00673" iyz="-0.000572" izz="0.000766"/>
  </inertial>
  <visual>
    <origin rpy="0 0 0" xyz="-0.033402 -0.040717 -0.098381"/>
    <geometry>
      <mesh filename="package://sample_description/meshes/arm_link_1.stl" scale="0.001 0.001 0.001"/>
    </geometry>
    <material name="silver"/>
  </visual>
  <collision>
    <origin rpy="0 0 0" xyz="-0.033402 -0.040717 -0.098381"/>
    <geometry>
      <mesh filename="package://sample_description/meshes/arm_link_1.stl" scale="0.001 0.001 0.001"/>
    </geometry>
  </collision>
</link>

<link name="elbow_link_1">
  <inertial>
    <origin rpy="0 0 0" xyz="0.11339547794855018 0.012763172522973126 0.04198840306489471"/>
    <mass value="0.2638036919050309"/>
    <inertia ixx="0.000249" ixy="-5e-06" ixz="-0.000587" iyy="0.001837" iyz="-2e-06" izz="0.001618"/>
  </inertial>
  <visual>
    <origin rpy="0 0 0" xyz="-0.001766 -0.090635 -0.306065"/>
    <geometry>
      <mesh filename="package://sample_description/meshes/elbow_link_1.stl" scale="0.001 0.001 0.001"/>
    </geometry>
    <material name="silver"/>
  </visual>
  <collision>
    <origin rpy="0 0 0" xyz="-0.001766 -0.090635 -0.306065"/>
    <geometry>
      <mesh filename="package://sample_description/meshes/elbow_link_1.stl" scale="0.001 0.001 0.001"/>
    </geometry>
  </collision>
</link>

<link name="eef_1">
  <inertial>
    <origin rpy="0 0 0" xyz="0.011722308925633196 3.0127185601719342e-05 0.004339403955303189"/>
    <mass value="0.20699557428756424"/>
    <inertia ixx="0.00028" ixy="9e-06" ixz="1.1e-05" iyy="5.6e-05" iyz="-2.3e-05" izz="0.000254"/>
  </inertial>
  <visual>
    <origin rpy="0 0 0" xyz="-0.236185 -0.103744 -0.392854"/>
    <geometry>
      <mesh filename="package://sample_description/meshes/eef_1.stl" scale="0.001 0.001 0.001"/>
    </geometry>
    <material name="silver"/>
  </visual>
  <collision>
    <origin rpy="0 0 0" xyz="-0.236185 -0.103744 -0.392854"/>
    <geometry>
      <mesh filename="package://sample_description/meshes/eef_1.stl" scale="0.001 0.001 0.001"/>
    </geometry>
  </collision>
</link>

<link name="left_claw_1">
  <inertial>
    <origin rpy="0 0 0" xyz="0.020752566356530777 0.007494276737303698 0.008699748789039063"/>
    <mass value="0.0188325"/>
    <inertia ixx="2e-06" ixy="-0.0" ixz="-1e-06" iyy="5e-06" iyz="0.0" izz="3e-06"/>
  </inertial>
  <visual>
    <origin rpy="0 0 0" xyz="-0.262416 -0.044292 -0.394423"/>
    <geometry>
      <mesh filename="package://sample_description/meshes/left_claw_1.stl" scale="0.001 0.001 0.001"/>
    </geometry>
    <material name="silver"/>
  </visual>
  <collision>
    <origin rpy="0 0 0" xyz="-0.262416 -0.044292 -0.394423"/>
    <geometry>
      <mesh filename="package://sample_description/meshes/left_claw_1.stl" scale="0.001 0.001 0.001"/>
    </geometry>
  </collision>
</link>

<link name="right_claw_1">
  <inertial>
    <origin rpy="0 0 0" xyz="0.02144932038856384 -0.007384617857163517 0.006922053805375028"/>
    <mass value="0.0188325"/>
    <inertia ixx="2e-06" ixy="-0.0" ixz="-1e-06" iyy="5e-06" iyz="0.0" izz="3e-06"/>
  </inertial>
  <visual>
    <origin rpy="0 0 0" xyz="-0.256843 -0.163317 -0.408643"/>
    <geometry>
      <mesh filename="package://sample_description/meshes/right_claw_1.stl" scale="0.001 0.001 0.001"/>
    </geometry>
    <material name="silver"/>
  </visual>
  <collision>
    <origin rpy="0 0 0" xyz="-0.256843 -0.163317 -0.408643"/>
    <geometry>
      <mesh filename="package://sample_description/meshes/right_claw_1.stl" scale="0.001 0.001 0.001"/>
    </geometry>
  </collision>
</link>

<joint name="base_twist" type="continuous">
  <origin rpy="0 0 0" xyz="0.033402 0.040717 0.050881"/>
  <parent link="base_link"/>
  <child link="shoulder_link_1"/>
  <axis xyz="0.0 0.0 1.0"/>
</joint>

<joint name="arm_rev" type="revolute">
  <origin rpy="0 0 0" xyz="0.0 0.0 0.0475"/>
  <parent link="shoulder_link_1"/>
  <child link="arm_link_1"/>
  <axis xyz="0.002596 -0.999997 -0.0"/>
  <limit effort="100" lower="-0.174533" upper="1.570796" velocity="100"/>
</joint>

<joint name="elbow_rev" type="revolute">
  <origin rpy="0 0 0" xyz="-0.031636 0.049918 0.207684"/>
  <parent link="arm_link_1"/>
  <child link="elbow_link_1"/>
  <axis xyz="-0.002596 0.999997 0.0"/>
  <limit effort="100" lower="-2.792527" upper="2.792527" velocity="100"/>
</joint>

<joint name="wrist_twist" type="continuous">
  <origin rpy="0 0 0" xyz="0.234419 0.013109 0.086789"/>
  <parent link="elbow_link_1"/>
  <child link="eef_1"/>
  <axis xyz="0.937804 0.002434 0.347157"/>
</joint>

<joint name="left_claw_sliding" type="prismatic">
  <origin rpy="0 0 0" xyz="0.026231 -0.059452 0.001569"/>
  <parent link="eef_1"/>
  <child link="left_claw_1"/>
  <axis xyz="-0.04644 0.991868 0.118498"/>
  <limit effort="100" lower="0.0" upper="0.05" velocity="100"/>
</joint>

<joint name="right_claw_sliding" type="prismatic">
  <origin rpy="0 0 0" xyz="0.020658 0.059573 0.015789"/>
  <parent link="eef_1"/>
  <child link="right_claw_1"/>
  <axis xyz="0.04644 -0.991868 -0.118498"/>
  <limit effort="100" lower="0.0" upper="0.05" velocity="100"/>
</joint>

</robot>
